/home/rishubhp/miniconda3/envs/contwords/lib/python3.9/site-packages/torchvision/io/image.py:13: UserWarning: Failed to load image Python extension: '/home/rishubhp/miniconda3/envs/contwords/lib/python3.9/site-packages/torchvision/image.so: undefined symbol: _ZN3c1017RegisterOperatorsD1Ev'If you don't plan on using image functionality from `torchvision.io`, you can ignore this warning. Otherwise, there might be something wrong with your environment. Did you have `libjpeg` or `libpng` installed before building `torchvision` from source?
  warn(
/home/rishubhp/miniconda3/envs/contwords/lib/python3.9/site-packages/xformers/ops/fmha/flash.py:211: FutureWarning: `torch.library.impl_abstract` was renamed to `torch.library.register_fake`. Please use that instead; we will remove `torch.library.impl_abstract` in a future version of PyTorch.
  @torch.library.impl_abstract("xformers_flash::flash_fwd")
/home/rishubhp/miniconda3/envs/contwords/lib/python3.9/site-packages/xformers/ops/fmha/flash.py:344: FutureWarning: `torch.library.impl_abstract` was renamed to `torch.library.register_fake`. Please use that instead; we will remove `torch.library.impl_abstract` in a future version of PyTorch.
  @torch.library.impl_abstract("xformers_flash::flash_bwd")
VLOG_STEPS = [100, 50000, 100000, 150000, 200000]
SAVE_STEPS = [500, 1000, 5000, 10000, 20000, 30000, 40000, 50000, 60000, 70000, 80000, 90000, 100000, 110000, 120000, 130000, 140000, 150000, 160000, 170000, 180000, 190000, 200000]
/home/rishubhp/miniconda3/envs/contwords/lib/python3.9/site-packages/huggingface_hub/file_download.py:1150: FutureWarning: `resume_download` is deprecated and will be removed in version 1.0.0. Downloads always resume when possible. If you want to force a new download, use `force_download=True`.
  warnings.warn(
Updating cross attention only!
['CrossAttnDownBlock2D', 'Attention', 'Attention', 'GEGLU', 'Attention', 'Attention', 'GEGLU', 'CrossAttnDownBlock2D', 'Attention', 'Attention', 'GEGLU', 'Attention', 'Attention', 'GEGLU', 'CrossAttnDownBlock2D', 'Attention', 'Attention', 'GEGLU', 'Attention', 'Attention', 'GEGLU', 'CrossAttnUpBlock2D', 'Attention', 'Attention', 'GEGLU', 'Attention', 'Attention', 'GEGLU', 'Attention', 'Attention', 'GEGLU', 'CrossAttnUpBlock2D', 'Attention', 'Attention', 'GEGLU', 'Attention', 'Attention', 'GEGLU', 'Attention', 'Attention', 'GEGLU', 'CrossAttnUpBlock2D', 'Attention', 'Attention', 'GEGLU', 'Attention', 'Attention', 'GEGLU', 'Attention', 'Attention', 'GEGLU', 'UNetMidBlock2DCrossAttn', 'Attention', 'Attention', 'GEGLU']
Differences: 0
/home/rishubhp/miniconda3/envs/contwords/lib/python3.9/site-packages/diffusers/configuration_utils.py:215: FutureWarning: It is deprecated to pass a pretrained model name or path to `from_config`.If you were trying to load a scheduler, please use <class 'diffusers.schedulers.scheduling_ddpm.DDPMScheduler'>.from_pretrained(...) instead. Otherwise, please make sure to pass a configuration dictionary instead. This functionality will be removed in v1.0.0.
  deprecate("config-passed-as-path", "1.0.0", deprecation_message, standard_warn=False)
  0%|          | 0/200000 [00:00<?, ?it/s][rank0]: Traceback (most recent call last):
[rank0]:   File "/home/rishubhp/vaibhav/meesho-project/training_scripts/train.py", line 2078, in <module>
[rank0]:     main(args)
[rank0]:   File "/home/rishubhp/vaibhav/meesho-project/training_scripts/train.py", line 1105, in main
[rank0]:     shutil.rmtree(f"vis") 
[rank0]:   File "/home/rishubhp/miniconda3/envs/contwords/lib/python3.9/shutil.py", line 740, in rmtree
[rank0]:     onerror(os.rmdir, path, sys.exc_info())
[rank0]:   File "/home/rishubhp/miniconda3/envs/contwords/lib/python3.9/shutil.py", line 738, in rmtree
[rank0]:     os.rmdir(path)
[rank0]: OSError: [Errno 39] Directory not empty: 'vis'
  0%|          | 0/200000 [00:01<?, ?it/s]
E0821 12:02:10.041299 139887984490304 torch/distributed/elastic/multiprocessing/api.py:833] failed (exitcode: 1) local_rank: 0 (pid: 1389852) of binary: /home/rishubhp/miniconda3/envs/contwords/bin/python
Traceback (most recent call last):
  File "/home/rishubhp/miniconda3/envs/contwords/bin/accelerate", line 8, in <module>
    sys.exit(main())
  File "/home/rishubhp/miniconda3/envs/contwords/lib/python3.9/site-packages/accelerate/commands/accelerate_cli.py", line 45, in main
    args.func(args)
  File "/home/rishubhp/miniconda3/envs/contwords/lib/python3.9/site-packages/accelerate/commands/launch.py", line 914, in launch_command
    multi_gpu_launcher(args)
  File "/home/rishubhp/miniconda3/envs/contwords/lib/python3.9/site-packages/accelerate/commands/launch.py", line 603, in multi_gpu_launcher
    distrib_run.run(args)
  File "/home/rishubhp/miniconda3/envs/contwords/lib/python3.9/site-packages/torch/distributed/run.py", line 892, in run
    elastic_launch(
  File "/home/rishubhp/miniconda3/envs/contwords/lib/python3.9/site-packages/torch/distributed/launcher/api.py", line 133, in __call__
    return launch_agent(self._config, self._entrypoint, list(args))
  File "/home/rishubhp/miniconda3/envs/contwords/lib/python3.9/site-packages/torch/distributed/launcher/api.py", line 264, in launch_agent
    raise ChildFailedError(
torch.distributed.elastic.multiprocessing.errors.ChildFailedError: 
============================================================
train.py FAILED
------------------------------------------------------------
Failures:
  <NO_OTHER_FAILURES>
------------------------------------------------------------
Root Cause (first observed failure):
[0]:
  time      : 2024-08-21_12:02:10
  host      : cn2.cds.iisc.in
  rank      : 0 (local_rank: 0)
  exitcode  : 1 (pid: 1389852)
  error_file: <N/A>
  traceback : To enable traceback see: https://pytorch.org/docs/stable/elastic/errors.html
============================================================
